<?xml version="1.0" ?>
<!-- Generated using onshape-to-robot -->
<!-- Onshape document_id f0912ad76048a2e7ed12d76c -->
<robot name="abb_arm">
  <!-- Link polisher -->
  <link name="polisher">
    <inertial>
      <origin xyz="0.949371 -0.158701 1.29896" rpy="0 0 0"/>
      <mass value="5.718"/>
      <inertia ixx="0.0864592" ixy="-0.00326117" ixz="0.0032624" iyy="0.0497535" iyz="-0.000294878" izz="0.0497589"/>
    </inertial>
    <!-- Part polisher -->
    <visual>
      <origin xyz="-0.193735 -0.0462556 -0.377109" rpy="0.00762499 -0.0869335 -0.0875981"/>
      <geometry>
        <mesh filename="package://abb_arm_description/abb_arm/assets/polisher.stl"/>
      </geometry>
      <material name="polisher_material">
        <color rgba="0.627451 0.627451 0.627451 1"/>
      </material>
    </visual>
    <collision>
      <origin xyz="-0.193735 -0.0462556 -0.377109" rpy="0.00762499 -0.0869335 -0.0875981"/>
      <geometry>
        <mesh filename="package://abb_arm_description/abb_arm/assets/polisher.stl"/>
      </geometry>
    </collision>
    <!-- Part irb4600_60kg_205_link6_cad_rev04_v1 -->
    <visual>
      <origin xyz="-0.223542 -0.0436409 -0.379314" rpy="0.00762499 -0.0869335 -0.0875981"/>
      <geometry>
        <mesh filename="package://abb_arm_description/abb_arm/assets/irb4600_60kg_205_link6_cad_rev04_v1.stl"/>
      </geometry>
      <material name="irb4600_60kg_205_link6_cad_rev04_v1_material">
        <color rgba="0.501961 0.501961 0.501961 1"/>
      </material>
    </visual>
    <collision>
      <origin xyz="-0.223542 -0.0436409 -0.379314" rpy="0.00762499 -0.0869335 -0.0875981"/>
      <geometry>
        <mesh filename="package://abb_arm_description/abb_arm/assets/irb4600_60kg_205_link6_cad_rev04_v1.stl"/>
      </geometry>
    </collision>
    <!-- Part polisher_2 -->
    <visual>
      <origin xyz="-0.223542 -0.0436409 -0.379314" rpy="0.00762499 -0.0869335 -0.0875981"/>
      <geometry>
        <mesh filename="package://abb_arm_description/abb_arm/assets/polisher__2.stl"/>
      </geometry>
      <material name="polisher_2_material">
        <color rgba="0.627451 0.627451 0.627451 1"/>
      </material>
    </visual>
    <collision>
      <origin xyz="-0.223542 -0.0436409 -0.379314" rpy="0.00762499 -0.0869335 -0.0875981"/>
      <geometry>
        <mesh filename="package://abb_arm_description/abb_arm/assets/polisher__2.stl"/>
      </geometry>
    </collision>
  </link>
  <!-- Link irb4600_60kg_205_link5_cad_rev04_v1 -->
  <link name="irb4600_60kg_205_link5_cad_rev04_v1">
    <inertial>
      <origin xyz="-0.0034515 0.00040032 -0.0660508" rpy="0 0 0"/>
      <mass value="4.058"/>
      <inertia ixx="0.0084813" ixy="-1.38141e-05" ixz="-2.08952e-06" iyy="0.00900393" iyz="-4.61387e-05" izz="0.00817587"/>
    </inertial>
    <!-- Part irb4600_60kg_205_link5_cad_rev04_v1 -->
    <visual>
      <origin xyz="-7.45683e-08 -1.57 -1.2" rpy="-1.5708 -1.5708 0"/>
      <geometry>
        <mesh filename="package://abb_arm_description/abb_arm/assets/irb4600_60kg_205_link5_cad_rev04_v1.stl"/>
      </geometry>
      <material name="irb4600_60kg_205_link5_cad_rev04_v1_material">
        <color rgba="0.843137 0.843137 0.843137 1"/>
      </material>
    </visual>
    <collision>
      <origin xyz="-7.45683e-08 -1.57 -1.2" rpy="-1.5708 -1.5708 0"/>
      <geometry>
        <mesh filename="package://abb_arm_description/abb_arm/assets/irb4600_60kg_205_link5_cad_rev04_v1.stl"/>
      </geometry>
    </collision>
  </link>
  <!-- Link irb4600_60kg_205_link4_cad_rev04_v1 -->
  <link name="irb4600_60kg_205_link4_cad_rev04_v1">
    <inertial>
      <origin xyz="-0.226768 0.00284651 0.0650243" rpy="0 0 0"/>
      <mass value="29.998"/>
      <inertia ixx="0.143764" ixy="-0.00617296" ixz="0.0152437" iyy="1.29389" iyz="-7.78483e-05" izz="1.24629"/>
    </inertial>
    <!-- Part irb4600_60kg_205_link4_cad_rev04_v1 -->
    <visual>
      <origin xyz="-1.135 1.57 0.067" rpy="1.5708 1.80845e-16 -3.747e-16"/>
      <geometry>
        <mesh filename="package://abb_arm_description/abb_arm/assets/irb4600_60kg_205_link4_cad_rev04_v1.stl"/>
      </geometry>
      <material name="irb4600_60kg_205_link4_cad_rev04_v1_material">
        <color rgba="0.843137 0.843137 0.843137 1"/>
      </material>
    </visual>
    <collision>
      <origin xyz="-1.135 1.57 0.067" rpy="1.5708 1.80845e-16 -3.747e-16"/>
      <geometry>
        <mesh filename="package://abb_arm_description/abb_arm/assets/irb4600_60kg_205_link4_cad_rev04_v1.stl"/>
      </geometry>
    </collision>
  </link>
  <!-- Link irb4600_60kg_205_link3_cad_rev04_v1 -->
  <link name="irb4600_60kg_205_link3_cad_rev04_v1">
    <inertial>
      <origin xyz="0.0492666 -0.0562381 -0.299387" rpy="0 0 0"/>
      <mass value="138.137"/>
      <inertia ixx="3.75533" ixy="-0.0381456" ixz="0.199072" iyy="3.08575" iyz="-0.317854" izz="3.06752"/>
    </inertial>
    <!-- Part irb4600_60kg_205_link3_cad_rev04_v1 -->
    <visual>
      <origin xyz="7.456e-08 -1.57 -0.5151" rpy="-1.5708 -1.5708 0"/>
      <geometry>
        <mesh filename="package://abb_arm_description/abb_arm/assets/irb4600_60kg_205_link3_cad_rev04_v1.stl"/>
      </geometry>
      <material name="irb4600_60kg_205_link3_cad_rev04_v1_material">
        <color rgba="0.843137 0.843137 0.843137 1"/>
      </material>
    </visual>
    <collision>
      <origin xyz="7.456e-08 -1.57 -0.5151" rpy="-1.5708 -1.5708 0"/>
      <geometry>
        <mesh filename="package://abb_arm_description/abb_arm/assets/irb4600_60kg_205_link3_cad_rev04_v1.stl"/>
      </geometry>
    </collision>
  </link>
  <!-- Link irb4600_60kg_205_link2_cad_rev04_v1 -->
  <link name="irb4600_60kg_205_link2_cad_rev04_v1">
    <inertial>
      <origin xyz="9.441e-05 0.503249 -0.0213536" rpy="0 0 0"/>
      <mass value="75.819"/>
      <inertia ixx="5.85954" ixy="-0.000648996" ixz="-6.39564e-08" iyy="0.434415" iyz="-0.198731" izz="6.07168"/>
    </inertial>
    <!-- Part irb4600_60kg_205_link2_cad_rev04_v1 -->
    <visual>
      <origin xyz="-0.175 1.395 0.1492" rpy="1.5708 -2.89807e-16 9.32928e-09"/>
      <geometry>
        <mesh filename="package://abb_arm_description/abb_arm/assets/irb4600_60kg_205_link2_cad_rev04_v1.stl"/>
      </geometry>
      <material name="irb4600_60kg_205_link2_cad_rev04_v1_material">
        <color rgba="0.843137 0.843137 0.843137 1"/>
      </material>
    </visual>
    <collision>
      <origin xyz="-0.175 1.395 0.1492" rpy="1.5708 -2.89807e-16 9.32928e-09"/>
      <geometry>
        <mesh filename="package://abb_arm_description/abb_arm/assets/irb4600_60kg_205_link2_cad_rev04_v1.stl"/>
      </geometry>
    </collision>
  </link>
  <!-- Link irb4600_60kg_205_link1_cad_rev04_v1 -->
  <link name="irb4600_60kg_205_link1_cad_rev04_v1">
    <inertial>
      <origin xyz="-0.0374366 -0.131082 -0.14719" rpy="0 0 0"/>
      <mass value="114.511"/>
      <inertia ixx="3.7354" ixy="-0.45961" ixz="0.0868632" iyy="2.39992" iyz="0.372701" izz="3.91333"/>
    </inertial>
    <!-- Part irb4600_60kg_205_link1_cad_rev04_v1 -->
    <visual>
      <origin xyz="0.0959456 -0.516183 -0.1225" rpy="-1.5708 1.22298e-16 0.523599"/>
      <geometry>
        <mesh filename="package://abb_arm_description/abb_arm/assets/irb4600_60kg_205_link1_cad_rev04_v1.stl"/>
      </geometry>
      <material name="irb4600_60kg_205_link1_cad_rev04_v1_material">
        <color rgba="0.843137 0.843137 0.843137 1"/>
      </material>
    </visual>
    <collision>
      <origin xyz="0.0959456 -0.516183 -0.1225" rpy="-1.5708 1.22298e-16 0.523599"/>
      <geometry>
        <mesh filename="package://abb_arm_description/abb_arm/assets/irb4600_60kg_205_link1_cad_rev04_v1.stl"/>
      </geometry>
    </collision>
  </link>
  <!-- Link irb4600_60kg_205_base_cad_rev05_v1 -->
  <link name="irb4600_60kg_205_base_cad_rev05_v1">
    <inertial>
      <origin xyz="-0.0911781 0.00036329 -0.0770452" rpy="0 0 0"/>
      <mass value="81.759"/>
      <inertia ixx="1.1426" ixy="0.0105896" ixz="0.156454" iyy="2.32048" iyz="0.000392078" izz="3.13396"/>
    </inertial>
    <!-- Part irb4600_60kg_205_base_cad_rev05_v1 -->
    <visual>
      <origin xyz="-1.66533e-16 -1.38778e-17 -0.1595" rpy="2.34188e-17 1.11022e-15 -4.64812e-08"/>
      <geometry>
        <mesh filename="package://abb_arm_description/abb_arm/assets/irb4600_60kg_205_base_cad_rev05_v1.stl"/>
      </geometry>
      <material name="irb4600_60kg_205_base_cad_rev05_v1_material">
        <color rgba="0.843137 0.843137 0.843137 1"/>
      </material>
    </visual>
    <collision>
      <origin xyz="-1.66533e-16 -1.38778e-17 -0.1595" rpy="2.34188e-17 1.11022e-15 -4.64812e-08"/>
      <geometry>
        <mesh filename="package://abb_arm_description/abb_arm/assets/irb4600_60kg_205_base_cad_rev05_v1.stl"/>
      </geometry>
    </collision>
  </link>
  <!-- Joint from irb4600_60kg_205_link1_cad_rev04_v1 to irb4600_60kg_205_base_cad_rev05_v1 -->
  <joint name="joint1" type="revolute">
    <origin xyz="0.0161956 -0.378052 -0.1225" rpy="-1.5708 1.22298e-16 0.523599"/>
    <parent link="irb4600_60kg_205_link1_cad_rev04_v1"/>
    <child link="irb4600_60kg_205_base_cad_rev05_v1"/>
    <axis xyz="0 0 1"/>
    <limit effort="10" velocity="10" lower="-3.141592653589793" upper="3.141592653589793"/>
  </joint>
  <!-- Joint from irb4600_60kg_205_link2_cad_rev04_v1 to irb4600_60kg_205_link1_cad_rev04_v1 -->
  <joint name="joint2" type="revolute">
    <origin xyz="-8.39635e-09 0.9 0.0267" rpy="3.14159 -2.62052e-16 9.32928e-09"/>
    <parent link="irb4600_60kg_205_link2_cad_rev04_v1"/>
    <child link="irb4600_60kg_205_link1_cad_rev04_v1"/>
    <axis xyz="0 0 1"/>
    <limit effort="10" velocity="10" lower="-3.141592653589793" upper="3.141592653589793"/>
  </joint>
  <!-- Joint from irb4600_60kg_205_link3_cad_rev04_v1 to irb4600_60kg_205_link2_cad_rev04_v1 -->
  <joint name="joint3" type="revolute">
    <origin xyz="-0.1492 -0.175 -0.3401" rpy="-3.14159 -1.5708 0"/>
    <parent link="irb4600_60kg_205_link3_cad_rev04_v1"/>
    <child link="irb4600_60kg_205_link2_cad_rev04_v1"/>
    <axis xyz="0 0 1"/>
    <limit effort="10" velocity="10" lower="-3.141592653589793" upper="3.141592653589793"/>
  </joint>
  <!-- Joint from irb4600_60kg_205_link4_cad_rev04_v1 to irb4600_60kg_205_link3_cad_rev04_v1 -->
  <joint name="joint4" type="revolute">
    <origin xyz="-0.6199 4.44089e-16 0.067" rpy="3.14159 -1.5708 0"/>
    <parent link="irb4600_60kg_205_link4_cad_rev04_v1"/>
    <child link="irb4600_60kg_205_link3_cad_rev04_v1"/>
    <axis xyz="0 0 1"/>
    <limit effort="10" velocity="10" lower="-3.141592653589793" upper="3.141592653589793"/>
  </joint>
  <!-- Joint from irb4600_60kg_205_link5_cad_rev04_v1 to irb4600_60kg_205_link4_cad_rev04_v1 -->
  <joint name="joint5" type="revolute">
    <origin xyz="-0.067 3.18222e-09 -0.065" rpy="3.14159 -1.5708 0"/>
    <parent link="irb4600_60kg_205_link5_cad_rev04_v1"/>
    <child link="irb4600_60kg_205_link4_cad_rev04_v1"/>
    <axis xyz="0 0 1"/>
    <limit effort="10" velocity="10" lower="-3.141592653589793" upper="3.141592653589793"/>
  </joint>
  <!-- Joint from polisher to irb4600_60kg_205_link5_cad_rev04_v1 -->
  <joint name="joint6" type="revolute">
    <origin xyz="0.830508 -0.148228 1.2889" rpy="1.48386 -0.0075962 1.48386"/>
    <parent link="polisher"/>
    <child link="irb4600_60kg_205_link5_cad_rev04_v1"/>
    <axis xyz="0 0 1"/>
    <limit effort="10" velocity="10" lower="-3.141592653589793" upper="3.141592653589793"/>
  </joint>
</robot>
