<?xml version="1.0" ?>
<!-- =================================================================================== -->
<!-- |    This document was autogenerated by xacro from robot.urdf.xacro               | -->
<!-- |    EDITING THIS FILE BY HAND IS NOT RECOMMENDED                                 | -->
<!-- =================================================================================== -->
<robot name="abb_arm">
  <!-- Specify some standard inertial calculations https://en.wikipedia.org/wiki/List_of_moments_of_inertia -->
  <!-- These make use of xacro's mathematical functionality -->
  <!-- Include platform -->
  <!-- <xacro:include filename="$(find abb_arm_description)/urdf/platform.xacro"/> -->
  <!-- Base link -->
  <link name="base_link"/>
  <!-- Link irb4600_60kg_205_base_cad_rev05_v1 -->
  <link name="irb4600_60kg_205_base_cad_rev05_v1">
    <inertial>
      <origin rpy="0 0 0" xyz="-0.321182 -0.0353324 -0.305087"/>
      <mass value="81.759"/>
      <inertia ixx="1.14136" ixy="0.113422" ixz="-0.0184365" iyy="2.30969" iyz="-0.00337268" izz="3.14598"/>
    </inertial>
    <!-- Part irb4600_60kg_205_base_cad_rev05_v1 -->
    <visual>
      <origin rpy="0.00762494 -0.0869335 -0.0875981" xyz="-0.223542 -0.043641 -0.379314"/>
      <geometry>
        <mesh filename="file:///home/brian_2025/Github/moveit_ws/install/abb_arm_description/share/abb_arm_description/assets/abb_arm/irb4600_60kg_205_base_cad_rev05_v1.stl"/>
      </geometry>
      <material name="irb4600_60kg_205_base_cad_rev05_v1_material">
        <color rgba="0.843137 0.843137 0.843137 1"/>
      </material>
    </visual>
    <collision>
      <origin rpy="0.00762494 -0.0869335 -0.0875981" xyz="-0.223542 -0.043641 -0.379314"/>
      <geometry>
        <mesh filename="file:///home/brian_2025/Github/moveit_ws/install/abb_arm_description/share/abb_arm_description/assets/abb_arm/irb4600_60kg_205_base_cad_rev05_v1.stl"/>
      </geometry>
    </collision>
  </link>
  <!-- Link irb4600_60kg_205_link1_cad_rev04_v1 -->
  <link name="irb4600_60kg_205_link1_cad_rev04_v1">
    <inertial>
      <origin rpy="0 0 0" xyz="0.0770381 -0.0246901 -0.240698"/>
      <mass value="114.511"/>
      <inertia ixx="3.00349" ixy="0.261576" ixz="0.808083" iyy="3.91333" iyz="-0.279337" izz="3.13182"/>
    </inertial>
    <!-- Part irb4600_60kg_205_link1_cad_rev04_v1 -->
    <visual>
      <origin rpy="-3.14159 2.77556e-17 -1.09504e-17" xyz="4.32987e-15 7.77156e-16 0.1595"/>
      <geometry>
        <mesh filename="file:///home/brian_2025/Github/moveit_ws/install/abb_arm_description/share/abb_arm_description/assets/abb_arm/irb4600_60kg_205_link1_cad_rev04_v1.stl"/>
      </geometry>
      <material name="irb4600_60kg_205_link1_cad_rev04_v1_material">
        <color rgba="0.843137 0.843137 0.843137 1"/>
      </material>
    </visual>
    <collision>
      <origin rpy="-3.14159 2.77556e-17 -1.09504e-17" xyz="4.32987e-15 7.77156e-16 0.1595"/>
      <geometry>
        <mesh filename="file:///home/brian_2025/Github/moveit_ws/install/abb_arm_description/share/abb_arm_description/assets/abb_arm/irb4600_60kg_205_link1_cad_rev04_v1.stl"/>
      </geometry>
    </collision>
  </link>
  <!-- Link irb4600_60kg_205_link2_cad_rev04_v1 -->
  <link name="irb4600_60kg_205_link2_cad_rev04_v1">
    <inertial>
      <origin rpy="0 0 0" xyz="9.44147e-05 -0.396751 -0.0480536"/>
      <mass value="75.819"/>
      <inertia ixx="5.85954" ixy="-0.000649047" ixz="-6.58104e-08" iyy="0.434415" iyz="-0.198731" izz="6.07168"/>
    </inertial>
    <!-- Part irb4600_60kg_205_link2_cad_rev04_v1 -->
    <visual>
      <origin rpy="1.5708 -3.41524e-17 -1.38778e-17" xyz="-0.175 0.495 0.1225"/>
      <geometry>
        <mesh filename="file:///home/brian_2025/Github/moveit_ws/install/abb_arm_description/share/abb_arm_description/assets/abb_arm/irb4600_60kg_205_link2_cad_rev04_v1.stl"/>
      </geometry>
      <material name="irb4600_60kg_205_link2_cad_rev04_v1_material">
        <color rgba="0.843137 0.843137 0.843137 1"/>
      </material>
    </visual>
    <collision>
      <origin rpy="1.5708 -3.41524e-17 -1.38778e-17" xyz="-0.175 0.495 0.1225"/>
      <geometry>
        <mesh filename="file:///home/brian_2025/Github/moveit_ws/install/abb_arm_description/share/abb_arm_description/assets/abb_arm/irb4600_60kg_205_link2_cad_rev04_v1.stl"/>
      </geometry>
    </collision>
  </link>
  <!-- Link irb4600_60kg_205_link3_cad_rev04_v1 -->
  <link name="irb4600_60kg_205_link3_cad_rev04_v1">
    <inertial>
      <origin rpy="0 0 0" xyz="0.0407131 0.118762 -0.198467"/>
      <mass value="138.137"/>
      <inertia ixx="3.06752" ixy="-0.317854" ixz="-0.199072" iyy="3.08575" iyz="0.0381456" izz="3.75533"/>
    </inertial>
    <!-- Part irb4600_60kg_205_link3_cad_rev04_v1 -->
    <visual>
      <origin rpy="-1.5708 3.84892e-17 -1.38778e-17" xyz="-0.175 -1.395 -0.1492"/>
      <geometry>
        <mesh filename="file:///home/brian_2025/Github/moveit_ws/install/abb_arm_description/share/abb_arm_description/assets/abb_arm/irb4600_60kg_205_link3_cad_rev04_v1.stl"/>
      </geometry>
      <material name="irb4600_60kg_205_link3_cad_rev04_v1_material">
        <color rgba="0.843137 0.843137 0.843137 1"/>
      </material>
    </visual>
    <collision>
      <origin rpy="-1.5708 3.84892e-17 -1.38778e-17" xyz="-0.175 -1.395 -0.1492"/>
      <geometry>
        <mesh filename="file:///home/brian_2025/Github/moveit_ws/install/abb_arm_description/share/abb_arm_description/assets/abb_arm/irb4600_60kg_205_link3_cad_rev04_v1.stl"/>
      </geometry>
    </collision>
  </link>
  <!-- Link irb4600_60kg_205_link4_cad_rev04_v1 -->
  <link name="irb4600_60kg_205_link4_cad_rev04_v1">
    <inertial>
      <origin rpy="0 0 0" xyz="-0.00197572 0.00284651 -0.393132"/>
      <mass value="29.998"/>
      <inertia ixx="1.24629" ixy="-7.78483e-05" ixz="-0.0152437" iyy="1.29389" iyz="0.00617296" izz="0.143764"/>
    </inertial>
    <!-- Part irb4600_60kg_205_link4_cad_rev04_v1 -->
    <visual>
      <origin rpy="1.5708 1.5708 0" xyz="-2.08167e-16 1.57 0.5151"/>
      <geometry>
        <mesh filename="file:///home/brian_2025/Github/moveit_ws/install/abb_arm_description/share/abb_arm_description/assets/abb_arm/irb4600_60kg_205_link4_cad_rev04_v1.stl"/>
      </geometry>
      <material name="irb4600_60kg_205_link4_cad_rev04_v1_material">
        <color rgba="0.843137 0.843137 0.843137 1"/>
      </material>
    </visual>
    <collision>
      <origin rpy="1.5708 1.5708 0" xyz="-2.08167e-16 1.57 0.5151"/>
      <geometry>
        <mesh filename="file:///home/brian_2025/Github/moveit_ws/install/abb_arm_description/share/abb_arm_description/assets/abb_arm/irb4600_60kg_205_link4_cad_rev04_v1.stl"/>
      </geometry>
    </collision>
  </link>
  <!-- Link irb4600_60kg_205_link5_cad_rev04_v1 -->
  <link name="irb4600_60kg_205_link5_cad_rev04_v1">
    <inertial>
      <origin rpy="0 0 0" xyz="-0.00105077 0.00040032 -0.0635485"/>
      <mass value="4.058"/>
      <inertia ixx="0.00817587" ixy="-4.61387e-05" ixz="2.08952e-06" iyy="0.00900393" iyz="1.38141e-05" izz="0.0084813"/>
    </inertial>
    <!-- Part irb4600_60kg_205_link5_cad_rev04_v1 -->
    <visual>
      <origin rpy="-1.5708 -3.79471e-18 -1.38778e-17" xyz="-1.135 -1.57 -0.067"/>
      <geometry>
        <mesh filename="file:///home/brian_2025/Github/moveit_ws/install/abb_arm_description/share/abb_arm_description/assets/abb_arm/irb4600_60kg_205_link5_cad_rev04_v1.stl"/>
      </geometry>
      <material name="irb4600_60kg_205_link5_cad_rev04_v1_material">
        <color rgba="0.843137 0.843137 0.843137 1"/>
      </material>
    </visual>
    <collision>
      <origin rpy="-1.5708 -3.79471e-18 -1.38778e-17" xyz="-1.135 -1.57 -0.067"/>
      <geometry>
        <mesh filename="file:///home/brian_2025/Github/moveit_ws/install/abb_arm_description/share/abb_arm_description/assets/abb_arm/irb4600_60kg_205_link5_cad_rev04_v1.stl"/>
      </geometry>
    </collision>
  </link>
  <!-- Link irb4600_60kg_205_link6_cad_rev04_v1 -->
  <link name="irb4600_60kg_205_link6_cad_rev04_v1">
    <inertial>
      <origin rpy="0 0 0" xyz="-3.63266e-05 0.000333341 -0.119747"/>
      <mass value="5.718"/>
      <inertia ixx="0.0494659" ixy="7.19253e-06" ixz="1.27941e-05" iyy="0.0494712" iyz="2.70911e-05" izz="0.0870346"/>
    </inertial>
    <!-- Part polisher -->
    <visual>
      <origin rpy="1.5708 1.5708 0" xyz="8.04912e-16 1.5704 1.17"/>
      <geometry>
        <mesh filename="file:///home/brian_2025/Github/moveit_ws/install/abb_arm_description/share/abb_arm_description/assets/abb_arm/polisher.stl"/>
      </geometry>
      <material name="polisher_material">
        <color rgba="0.627451 0.627451 0.627451 1"/>
      </material>
    </visual>
    <collision>
      <origin rpy="1.5708 1.5708 0" xyz="8.04912e-16 1.5704 1.17"/>
      <geometry>
        <mesh filename="file:///home/brian_2025/Github/moveit_ws/install/abb_arm_description/share/abb_arm_description/assets/abb_arm/polisher.stl"/>
      </geometry>
    </collision>
    <!-- Part irb4600_60kg_205_link6_cad_rev04_v1 -->
    <visual>
      <origin rpy="1.5708 1.5708 0" xyz="1.66533e-16 1.57 1.2"/>
      <geometry>
        <mesh filename="file:///home/brian_2025/Github/moveit_ws/install/abb_arm_description/share/abb_arm_description/assets/abb_arm/irb4600_60kg_205_link6_cad_rev04_v1.stl"/>
      </geometry>
      <material name="irb4600_60kg_205_link6_cad_rev04_v1_material">
        <color rgba="0.501961 0.501961 0.501961 1"/>
      </material>
    </visual>
    <collision>
      <origin rpy="1.5708 1.5708 0" xyz="1.66533e-16 1.57 1.2"/>
      <geometry>
        <mesh filename="file:///home/brian_2025/Github/moveit_ws/install/abb_arm_description/share/abb_arm_description/assets/abb_arm/irb4600_60kg_205_link6_cad_rev04_v1.stl"/>
      </geometry>
    </collision>
    <!-- Part polisher_2 -->
    <visual>
      <origin rpy="1.5708 1.5708 0" xyz="7.35523e-16 1.57 1.2"/>
      <geometry>
        <mesh filename="file:///home/brian_2025/Github/moveit_ws/install/abb_arm_description/share/abb_arm_description/assets/abb_arm/polisher__2.stl"/>
      </geometry>
      <material name="polisher_2_material">
        <color rgba="0.627451 0.627451 0.627451 1"/>
      </material>
    </visual>
    <collision>
      <origin rpy="1.5708 1.5708 0" xyz="7.35523e-16 1.57 1.2"/>
      <geometry>
        <mesh filename="file:///home/brian_2025/Github/moveit_ws/install/abb_arm_description/share/abb_arm_description/assets/abb_arm/polisher__2.stl"/>
      </geometry>
    </collision>
  </link>
  <!-- Joint from irb4600_60kg_205_link5_cad_rev04_v1 to irb4600_60kg_205_link6_cad_rev04_v1 -->
  <joint name="joint6" type="revolute">
    <origin rpy="-3.14159 1.5708 0" xyz="0.065 -2.22045e-16 -0.067"/>
    <parent link="irb4600_60kg_205_link5_cad_rev04_v1"/>
    <child link="irb4600_60kg_205_link6_cad_rev04_v1"/>
    <axis xyz="0 0 1"/>
    <limit effort="1000" lower="-3.141592653589793" upper="3.141592653589793" velocity="10"/>
  </joint>
  <!-- Joint from irb4600_60kg_205_link4_cad_rev04_v1 to irb4600_60kg_205_link5_cad_rev04_v1 -->
  <joint name="joint5" type="revolute">
    <origin rpy="-3.14159 1.5708 0" xyz="-0.067 0 -0.6199"/>
    <parent link="irb4600_60kg_205_link4_cad_rev04_v1"/>
    <child link="irb4600_60kg_205_link5_cad_rev04_v1"/>
    <axis xyz="0 0 1"/>
    <limit effort="1000" lower="-3.141592653589793" upper="3.141592653589793" velocity="10"/>
  </joint>
  <!-- Joint from irb4600_60kg_205_link3_cad_rev04_v1 to irb4600_60kg_205_link4_cad_rev04_v1 -->
  <joint name="joint4" type="revolute">
    <origin rpy="3.14159 1.5708 0" xyz="0.3401 0.175 -0.1492"/>
    <parent link="irb4600_60kg_205_link3_cad_rev04_v1"/>
    <child link="irb4600_60kg_205_link4_cad_rev04_v1"/>
    <axis xyz="0 0 1"/>
    <limit effort="1000" lower="-3.141592653589793" upper="3.141592653589793" velocity="10"/>
  </joint>
  <!-- Joint from irb4600_60kg_205_link2_cad_rev04_v1 to irb4600_60kg_205_link3_cad_rev04_v1 -->
  <joint name="joint3" type="revolute">
    <origin rpy="-3.14159 3.06829e-17 1.63897e-14" xyz="1.38778e-17 -0.9 -0.0267"/>
    <parent link="irb4600_60kg_205_link2_cad_rev04_v1"/>
    <child link="irb4600_60kg_205_link3_cad_rev04_v1"/>
    <axis xyz="0 0 1"/>
    <limit effort="1000" lower="-3.141592653589793" upper="3.141592653589793" velocity="10"/>
  </joint>
  <!-- Joint from irb4600_60kg_205_link1_cad_rev04_v1 to irb4600_60kg_205_link2_cad_rev04_v1 -->
  <joint name="joint2" type="revolute">
    <origin rpy="1.5708 -1.6237e-15 -1.44199e-17" xyz="0.175 0.1225 -0.3355"/>
    <parent link="irb4600_60kg_205_link1_cad_rev04_v1"/>
    <child link="irb4600_60kg_205_link2_cad_rev04_v1"/>
    <axis xyz="0 0 1"/>
    <limit effort="1000" lower="-3.141592653589793" upper="3.141592653589793" velocity="10"/>
  </joint>
  <!-- Joint from irb4600_60kg_205_base_cad_rev05_v1 to irb4600_60kg_205_link1_cad_rev04_v1 -->
  <joint name="joint1" type="revolute">
    <origin rpy="-3.13397 -0.0869335 -0.0875981" xyz="-0.237443 -0.043641 -0.220421"/>
    <parent link="irb4600_60kg_205_base_cad_rev05_v1"/>
    <child link="irb4600_60kg_205_link1_cad_rev04_v1"/>
    <axis xyz="0 0 1"/>
    <limit effort="1000" lower="-3.141592653589793" upper="3.141592653589793" velocity="10"/>
  </joint>
  <!-- Joint from base_link to base_cad -->
  <!-- <joint name="chassis_arm_base_joint" type="fixed">
    <origin xyz="0.3 0 0.65" rpy="0 0 0"/>
    <parent link="chassis"/>
    <child link="irb4600_60kg_205_base_cad_rev05_v1"/>
  </joint> -->
  <!-- Joint from base_plate to base_cad -->
  <joint name="base_plate_base_cad_joint" type="fixed">
    <origin rpy="0 0.08 0.1" xyz="0.62 0.08 0.391"/>
    <parent link="base_plate__mild_steel"/>
    <child link="irb4600_60kg_205_base_cad_rev05_v1"/>
  </joint>
  <!-- Link base_plate__mild_steel -->
  <link name="base_plate__mild_steel">
    <inertial>
      <origin rpy="0 0 0" xyz="-0.295151 0.0518164 0.226115"/>
      <mass value="591"/>
      <inertia ixx="84.5177" ixy="-4.82016" ixz="9.4146" iyy="98.5566" iyz="-7.20458" izz="93.259"/>
    </inertial>
    <!-- Part right_leg -->
    <visual>
      <origin rpy="0 -0 0" xyz="0 0 0"/>
      <geometry>
        <mesh filename="file:///home/brian_2025/Github/moveit_ws/install/abb_arm_description/share/abb_arm_description/assets/major_components/right_leg.stl"/>
      </geometry>
      <material name="right_leg_material">
        <color rgba="0.627451 0.627451 0.627451 1"/>
      </material>
    </visual>
    <collision>
      <origin rpy="0 -0 0" xyz="0 0 0"/>
      <geometry>
        <mesh filename="file:///home/brian_2025/Github/moveit_ws/install/abb_arm_description/share/abb_arm_description/assets/major_components/right_leg.stl"/>
      </geometry>
    </collision>
    <!-- Part vacuum_pump -->
    <visual>
      <origin rpy="0 -0 0" xyz="0 0 0"/>
      <geometry>
        <mesh filename="file:///home/brian_2025/Github/moveit_ws/install/abb_arm_description/share/abb_arm_description/assets/major_components/vacuum_pump.stl"/>
      </geometry>
      <material name="vacuum_pump_material">
        <color rgba="0.627451 0.627451 0.627451 1"/>
      </material>
    </visual>
    <collision>
      <origin rpy="0 -0 0" xyz="0 0 0"/>
      <geometry>
        <mesh filename="file:///home/brian_2025/Github/moveit_ws/install/abb_arm_description/share/abb_arm_description/assets/major_components/vacuum_pump.stl"/>
      </geometry>
    </collision>
    <!-- Part system_controller -->
    <visual>
      <origin rpy="0 -0 0" xyz="0 0 0"/>
      <geometry>
        <mesh filename="file:///home/brian_2025/Github/moveit_ws/install/abb_arm_description/share/abb_arm_description/assets/major_components/system_controller.stl"/>
      </geometry>
      <material name="system_controller_material">
        <color rgba="0.960784 0.960784 0.964706 1"/>
      </material>
    </visual>
    <collision>
      <origin rpy="0 -0 0" xyz="0 0 0"/>
      <geometry>
        <mesh filename="file:///home/brian_2025/Github/moveit_ws/install/abb_arm_description/share/abb_arm_description/assets/major_components/system_controller.stl"/>
      </geometry>
    </collision>
    <!-- Part compressor -->
    <visual>
      <origin rpy="0 -0 0" xyz="0 0 0"/>
      <geometry>
        <mesh filename="file:///home/brian_2025/Github/moveit_ws/install/abb_arm_description/share/abb_arm_description/assets/major_components/compressor.stl"/>
      </geometry>
      <material name="compressor_material">
        <color rgba="0.627451 0.627451 0.627451 1"/>
      </material>
    </visual>
    <collision>
      <origin rpy="0 -0 0" xyz="0 0 0"/>
      <geometry>
        <mesh filename="file:///home/brian_2025/Github/moveit_ws/install/abb_arm_description/share/abb_arm_description/assets/major_components/compressor.stl"/>
      </geometry>
    </collision>
    <!-- Part abb_controller -->
    <visual>
      <origin rpy="0 -0 0" xyz="0 0 0"/>
      <geometry>
        <mesh filename="file:///home/brian_2025/Github/moveit_ws/install/abb_arm_description/share/abb_arm_description/assets/major_components/abb_controller.stl"/>
      </geometry>
      <material name="abb_controller_material">
        <color rgba="0.960784 0.960784 0.964706 1"/>
      </material>
    </visual>
    <collision>
      <origin rpy="0 -0 0" xyz="0 0 0"/>
      <geometry>
        <mesh filename="file:///home/brian_2025/Github/moveit_ws/install/abb_arm_description/share/abb_arm_description/assets/major_components/abb_controller.stl"/>
      </geometry>
    </collision>
    <!-- Part counter_weight_2 -->
    <visual>
      <origin rpy="0 -0 0" xyz="0 0 0"/>
      <geometry>
        <mesh filename="file:///home/brian_2025/Github/moveit_ws/install/abb_arm_description/share/abb_arm_description/assets/major_components/counter_weight_2.stl"/>
      </geometry>
      <material name="counter_weight_2_material">
        <color rgba="0.796078 0.796078 0.796078 1"/>
      </material>
    </visual>
    <collision>
      <origin rpy="0 -0 0" xyz="0 0 0"/>
      <geometry>
        <mesh filename="file:///home/brian_2025/Github/moveit_ws/install/abb_arm_description/share/abb_arm_description/assets/major_components/counter_weight_2.stl"/>
      </geometry>
    </collision>
    <!-- Part base_plate__mild_steel -->
    <visual>
      <origin rpy="0 -0 0" xyz="0 0 0"/>
      <geometry>
        <mesh filename="file:///home/brian_2025/Github/moveit_ws/install/abb_arm_description/share/abb_arm_description/assets/major_components/base_plate__mild_steel.stl"/>
      </geometry>
      <material name="base_plate__mild_steel_material">
        <color rgba="0.1 0.1 0.1 1"/>
      </material>
    </visual>
    <collision>
      <origin rpy="0 -0 0" xyz="0 0 0"/>
      <geometry>
        <mesh filename="file:///home/brian_2025/Github/moveit_ws/install/abb_arm_description/share/abb_arm_description/assets/major_components/base_plate__mild_steel.stl"/>
      </geometry>
    </collision>
    <!-- Part counter_weight_1 -->
    <visual>
      <origin rpy="0 -0 0" xyz="0 0 0"/>
      <geometry>
        <mesh filename="file:///home/brian_2025/Github/moveit_ws/install/abb_arm_description/share/abb_arm_description/assets/major_components/counter_weight_1.stl"/>
      </geometry>
      <material name="counter_weight_1_material">
        <color rgba="0.796078 0.796078 0.796078 1"/>
      </material>
    </visual>
    <collision>
      <origin rpy="0 -0 0" xyz="0 0 0"/>
      <geometry>
        <mesh filename="file:///home/brian_2025/Github/moveit_ws/install/abb_arm_description/share/abb_arm_description/assets/major_components/counter_weight_1.stl"/>
      </geometry>
    </collision>
    <!-- Part left_leg -->
    <visual>
      <origin rpy="0 -0 0" xyz="0 0 0"/>
      <geometry>
        <mesh filename="file:///home/brian_2025/Github/moveit_ws/install/abb_arm_description/share/abb_arm_description/assets/major_components/left_leg.stl"/>
      </geometry>
      <material name="left_leg_material">
        <color rgba="0.627451 0.627451 0.627451 1"/>
      </material>
    </visual>
    <collision>
      <origin rpy="0 -0 0" xyz="0 0 0"/>
      <geometry>
        <mesh filename="file:///home/brian_2025/Github/moveit_ws/install/abb_arm_description/share/abb_arm_description/assets/major_components/left_leg.stl"/>
      </geometry>
    </collision>
  </link>
  <joint name="base_plate_mild_steel_joint" type="fixed">
    <parent link="base_link"/>
    <child link="base_plate__mild_steel"/>
    <origin rpy="0 0 0" xyz="0 0 0"/>
  </joint>
  <!-- Link mir_body -->
  <link name="mir_body">
    <inertial>
      <origin rpy="0 0 0" xyz="-1.10928e-16 -2.01686e-17 0.177103"/>
      <mass value="244"/>
      <inertia ixx="17.5393" ixy="1.29661e-14" ixz="0" iyy="37.4939" iyz="6.50391e-16" izz="51.4969"/>
    </inertial>
    <!-- Part mir_body -->
    <visual>
      <origin rpy="0 -0 0" xyz="0 0 0"/>
      <geometry>
        <mesh filename="file:///home/brian_2025/Github/moveit_ws/install/abb_arm_description/share/abb_arm_description/assets/mir_platform/mir_body.stl"/>
      </geometry>
      <material name="mir_body_material">
        <color rgba="0.964706 0.964706 0.952941 1"/>
      </material>
    </visual>
    <collision>
      <origin rpy="0 -0 0" xyz="0 0 0"/>
      <geometry>
        <mesh filename="file:///home/brian_2025/Github/moveit_ws/install/abb_arm_description/share/abb_arm_description/assets/mir_platform/mir_body.stl"/>
      </geometry>
    </collision>
    <!-- Part wheel_boundary -->
    <visual>
      <origin rpy="0 -0 0" xyz="0 0 0"/>
      <geometry>
        <mesh filename="file:///home/brian_2025/Github/moveit_ws/install/abb_arm_description/share/abb_arm_description/assets/mir_platform/wheel_boundary.stl"/>
      </geometry>
      <material name="wheel_boundary_material">
        <color rgba="0.701961 0.701961 0.701961 1"/>
      </material>
    </visual>
    <collision>
      <origin rpy="0 -0 0" xyz="0 0 0"/>
      <geometry>
        <mesh filename="file:///home/brian_2025/Github/moveit_ws/install/abb_arm_description/share/abb_arm_description/assets/mir_platform/wheel_boundary.stl"/>
      </geometry>
    </collision>
  </link>
  <joint name="base_to_mir_body" type="fixed">
    <parent link="base_plate__mild_steel"/>
    <child link="mir_body"/>
    <origin rpy="0 0 0" xyz="0 0 -0.3"/>
  </joint>
  <ros2_control name="ros2_control_system" type="system">
    <hardware>
      <plugin>gz_ros2_control/GazeboSimSystem</plugin>
    </hardware>
    <joint name="joint1">
      <command_interface name="position"/>
      <state_interface name="position">
        <param name="initial_value">0</param>
      </state_interface>
      <state_interface name="velocity"/>
    </joint>
    <joint name="joint2">
      <command_interface name="position"/>
      <state_interface name="position">
        <param name="initial_value">0</param>
      </state_interface>
      <state_interface name="velocity"/>
    </joint>
    <joint name="joint3">
      <command_interface name="position"/>
      <state_interface name="position">
        <param name="initial_value">0</param>
      </state_interface>
      <state_interface name="velocity"/>
    </joint>
    <joint name="joint4">
      <command_interface name="position"/>
      <state_interface name="position">
        <param name="initial_value">0</param>
      </state_interface>
      <state_interface name="velocity"/>
    </joint>
    <joint name="joint5">
      <command_interface name="position"/>
      <state_interface name="position">
        <param name="initial_value">0</param>
      </state_interface>
      <state_interface name="velocity"/>
    </joint>
    <joint name="joint6">
      <command_interface name="position"/>
      <state_interface name="position">
        <param name="initial_value">0</param>
      </state_interface>
      <state_interface name="velocity"/>
    </joint>
  </ros2_control>
  <gazebo>
    <plugin filename="gz_ros2_control-system" name="gz_ros2_control::GazeboSimROS2ControlPlugin">
      <robot_param>robot_description</robot_param>
      <robot_param_node>robot_state_publisher</robot_param_node>
      <parameters>/home/brian_2025/Github/moveit_ws/install/abb_arm_description/share/abb_arm_description/config/ros2_controllers.yaml</parameters>
    </plugin>
  </gazebo>
</robot>
